01:44:52 PM - ERROR -->  Exception occurred in main():
Traceback (most recent call last):
  File "C:\Users\VISHNUNATH\Desktop\auto-zoom-meetings\main.py", line 48, in <module>
    main()
    ~~~~^^
  File "C:\Users\VISHNUNATH\Desktop\auto-zoom-meetings\main.py", line 40, in main
    jsonschema.validate(config_data, CONFIG_SCHEMA)
    ^^^^^^^^^^
NameError: name 'jsonschema' is not defined

01:45:13 PM - INFO -->  Starting Zoom Meeting Bot...
01:45:13 PM - INFO -->  Meetings scheduled: [Meeting(join_time=2025-09-29 09:05:00, meeting_type=regular, link=link goes here), Meeting(join_time=2025-09-29 10:05:00, meeting_type=regular, link=link goes here), Meeting(join_time=2025-09-29 11:05:00, meeting_type=lab, link=link goes here), Meeting(join_time=2025-09-29 14:05:00, meeting_type=regular, link=link goes here), Meeting(join_time=2025-09-29 15:05:00, meeting_type=regular, link=link goes here), Meeting(join_time=2025-09-29 16:05:00, meeting_type=regular, link=link goes here)]
01:45:13 PM - INFO -->  Scheduler set up. Waiting to join meetings...
